user1@user1MBP:~/github/Crawling-ShortenedURL/siteSearch/twitterSearch$ time python3 twitterSearch-withYahooJp-rec.py > exampleResult-withYahoo-rec.txt
bit.ly
bit.ly
2008/09/25 ~ 2017/12/07
2017/10/12 ~ 2017/12/07
12914
2017/08/17 ~ 2017/10/12
16624
2017/06/22 ~ 2017/08/17
20148
2017/04/27 ~ 2017/06/22
23858
2017/03/02 ~ 2017/04/27
28056
2017/01/05 ~ 2017/03/02
39095
2016/11/10 ~ 2017/01/05
43766
2016/09/15 ~ 2016/11/10
56168
2016/07/21 ~ 2016/09/15
61672
2016/05/26 ~ 2016/07/21
62520
2016/03/31 ~ 2016/05/26
69472
2016/02/04 ~ 2016/03/31
Traceback (most recent call last):
  File "twitterSearch-withYahooJp-rec.py", line 96, in <module>
    driver.get(foundURL)
  File "/usr/local/lib/python3.6/site-packages/selene/common/delegation.py", line 6, in delegator
    return getattr(self.__delegate__, name)(*args, **kwargs)  # pragma: no cover
  File "/usr/local/lib/python3.6/site-packages/selenium/webdriver/remote/webdriver.py", line 245, in get
    self.execute(Command.GET, {'url': url})
  File "/usr/local/lib/python3.6/site-packages/selenium/webdriver/remote/webdriver.py", line 233, in execute
    self.error_handler.check_response(response)
  File "/usr/local/lib/python3.6/site-packages/selenium/webdriver/remote/errorhandler.py", line 194, in check_response
    raise exception_class(message, screen, stacktrace)
selenium.common.exceptions.TimeoutException: Message: timeout
  (Session info: chrome=62.0.3202.94)
  (Driver info: chromedriver=2.33.506106 (8a06c39c4582fbfbab6966dbb1c38a9173bfb1a2),platform=Mac OS X 10.13.1 x86_64)

Exception ignored in: <bound method Service.__del__ of <selenium.webdriver.chrome.service.Service object at 0x10fc22908>>
Traceback (most recent call last):
  File "/usr/local/lib/python3.6/site-packages/selenium/webdriver/common/service.py", line 151, in __del__
  File "/usr/local/lib/python3.6/site-packages/selenium/webdriver/common/service.py", line 127, in stop
  File "/usr/local/lib/python3.6/site-packages/selenium/webdriver/common/service.py", line 98, in send_remote_shutdown_command
ImportError: sys.meta_path is None, Python is likely shutting down

real	427m37.178s
user	1m3.780s
sys	0m4.884s
